2021-12-09 17:00:13,084 - apscheduler.scheduler - INFO - Scheduler started
2021-12-09 17:00:24,996 - root - INFO - Sending Dict/Lect -- dict/m/Audioperceptiva/3
2021-12-09 17:01:50,840 - root - INFO - Sending Dict/Lect -- dict/r/Audioperceptiva/C
2021-12-09 17:02:38,229 - root - INFO - Enviando solfeo -- dict/Suffern/3
2021-12-09 17:02:38,625 - root - ERROR - [Errno 2] No such file or directory: 'dict/Suffern/3/'
2021-12-09 17:04:34,417 - telegram.ext.updater - INFO - Received signal 2 (SIGINT), stopping...
2021-12-09 17:04:34,418 - apscheduler.scheduler - INFO - Scheduler has been shut down
2021-12-09 17:05:26,777 - apscheduler.scheduler - INFO - Scheduler started
2021-12-09 17:05:54,489 - root - INFO - Sending Dict/Lect -- dict/m/Audioperceptiva/2
2021-12-09 18:57:41,256 - root - INFO - Reporting
2021-12-09 19:02:57,059 - telegram.ext.updater - ERROR - Error while getting Updates: Bad Gateway
2021-12-09 19:02:57,060 - root - ERROR - Bad Gateway
2021-12-09 19:02:57,323 - telegram.ext.dispatcher - ERROR - An uncaught error was raised while handling the error.
Traceback (most recent call last):
  File "/usr/local/lib/python3.8/dist-packages/telegram/ext/dispatcher.py", line 536, in process_update
    self.dispatch_error(None, update)
  File "/usr/local/lib/python3.8/dist-packages/telegram/ext/dispatcher.py", line 810, in dispatch_error
    callback(update, context)
  File "BotTyP4.py", line 470, in error
    context.bot.sendMessage(chat_id=devid, text="Hubo un error " + str(context.error))
  File "/usr/local/lib/python3.8/dist-packages/telegram/bot.py", line 130, in decorator
    result = func(*args, **kwargs)
  File "/usr/local/lib/python3.8/dist-packages/telegram/bot.py", line 513, in send_message
    return self._message(  # type: ignore[return-value]
  File "/usr/local/lib/python3.8/dist-packages/telegram/ext/extbot.py", line 199, in _message
    result = super()._message(
  File "/usr/local/lib/python3.8/dist-packages/telegram/bot.py", line 332, in _message
    result = self._post(endpoint, data, timeout=timeout, api_kwargs=api_kwargs)
  File "/usr/local/lib/python3.8/dist-packages/telegram/bot.py", line 295, in _post
    return self.request.post(
  File "/usr/local/lib/python3.8/dist-packages/telegram/utils/request.py", line 356, in post
    result = self._request_wrapper(
  File "/usr/local/lib/python3.8/dist-packages/telegram/utils/request.py", line 290, in _request_wrapper
    raise NetworkError('Bad Gateway')
telegram.error.NetworkError: Bad Gateway
2021-12-09 19:45:07,742 - root - INFO - Sending Dict/Lect -- dict/m/Audioperceptiva/3
2021-12-09 19:45:46,429 - root - INFO - Sending Melo/Hind -- hind/X/142c
2021-12-09 19:46:05,795 - root - INFO - Sending Dict/Lect -- lect/r/Audioperceptiva/E
2021-12-09 19:47:16,532 - root - INFO - Enviando secuencia -- G/Menor natural/4
2021-12-09 19:47:27,664 - root - INFO - Enviando secuencia -- G/Menor natural/4
2021-12-09 22:21:59,032 - telegram.vendor.ptb_urllib3.urllib3.connectionpool - WARNING - Retrying (Retry(total=2, connect=None, read=None, redirect=None)) after connection broken by 'NewConnectionError('<telegram.vendor.ptb_urllib3.urllib3.connection.VerifiedHTTPSConnection object at 0x7fdd80e5edc0>: Failed to establish a new connection: [Errno 101] Network is unreachable')': /bot1965896728:AAFgG4MTLoLy8QnqINF4qLm4_umRJM7DJHo/getUpdates
2021-12-09 22:23:22,827 - telegram.vendor.ptb_urllib3.urllib3.connectionpool - WARNING - Retrying (Retry(total=2, connect=None, read=None, redirect=None)) after connection broken by 'NewConnectionError('<telegram.vendor.ptb_urllib3.urllib3.connection.VerifiedHTTPSConnection object at 0x7fdd80e5eb20>: Failed to establish a new connection: [Errno -3] Temporary failure in name resolution')': /bot1965896728:AAFgG4MTLoLy8QnqINF4qLm4_umRJM7DJHo/getUpdates
2021-12-09 23:23:36,506 - telegram.vendor.ptb_urllib3.urllib3.connectionpool - WARNING - Retrying (Retry(total=2, connect=None, read=None, redirect=None)) after connection broken by 'NewConnectionError('<telegram.vendor.ptb_urllib3.urllib3.connection.VerifiedHTTPSConnection object at 0x7fdd80e70250>: Failed to establish a new connection: [Errno -3] Temporary failure in name resolution')': /bot1965896728:AAFgG4MTLoLy8QnqINF4qLm4_umRJM7DJHo/getUpdates
2021-12-09 23:43:12,346 - telegram.vendor.ptb_urllib3.urllib3.connectionpool - WARNING - Retrying (Retry(total=2, connect=None, read=None, redirect=None)) after connection broken by 'ConnectTimeoutError(<telegram.vendor.ptb_urllib3.urllib3.connection.VerifiedHTTPSConnection object at 0x7fdd80ec6310>, 'Connection to api.telegram.org timed out. (connect timeout=5.0)')': /bot1965896728:AAFgG4MTLoLy8QnqINF4qLm4_umRJM7DJHo/getUpdates
2021-12-09 23:43:35,325 - telegram.vendor.ptb_urllib3.urllib3.connectionpool - WARNING - Retrying (Retry(total=2, connect=None, read=None, redirect=None)) after connection broken by 'ConnectTimeoutError(<telegram.vendor.ptb_urllib3.urllib3.connectionpool.HTTPSConnectionPool object at 0x7fdd847ea3a0>, 'Connect timed out. (connect timeout=5.0)')': /bot1965896728:AAFgG4MTLoLy8QnqINF4qLm4_umRJM7DJHo/getUpdates
2021-12-10 07:38:02,136 - root - INFO - Enviando solfeo -- dict/Suffern/4
2021-12-10 07:38:02,778 - root - ERROR - [Errno 2] No such file or directory: 'dict/Suffern/4/'
2021-12-10 07:38:36,000 - root - INFO - Sending Melo/Hind -- melo/VIII/258
2021-12-10 09:41:33,313 - root - INFO - Enviando secuencia -- C/Mayor/5
2021-12-10 09:43:13,956 - root - INFO - Enviando secuencia -- C/Mayor/5
2021-12-10 09:43:49,161 - root - INFO - Enviando secuencia -- C/Mayor/5
2021-12-10 09:44:54,577 - root - INFO - Enviando secuencia -- C/Mayor/5
2021-12-10 09:45:54,898 - root - INFO - Sending Dict/Lect -- lect/r/Audioperceptiva/B
2021-12-10 09:46:28,454 - root - INFO - Sending Dict/Lect -- lect/r/Audioperceptiva/C
2021-12-10 12:15:41,064 - root - INFO - Reporting
2021-12-10 14:06:00,853 - root - INFO - Sending Dict/Lect -- lect/r/Audioperceptiva/C
2021-12-10 14:06:57,921 - root - INFO - Sending Dict/Lect -- lect/m/Audioperceptiva/5
2021-12-10 14:16:16,750 - root - INFO - Sending Dict/Lect -- lect/m/Audioperceptiva/2
2021-12-10 16:36:12,405 - telegram.vendor.ptb_urllib3.urllib3.connectionpool - WARNING - Retrying (Retry(total=2, connect=None, read=None, redirect=None)) after connection broken by 'NewConnectionError('<telegram.vendor.ptb_urllib3.urllib3.connection.VerifiedHTTPSConnection object at 0x7fdd80e74760>: Failed to establish a new connection: [Errno -3] Temporary failure in name resolution')': /bot1965896728:AAFgG4MTLoLy8QnqINF4qLm4_umRJM7DJHo/getUpdates
2021-12-11 11:21:31,820 - root - INFO - Enviando secuencia -- C/Mayor/3
2021-12-11 11:22:01,532 - root - INFO - Enviando secuencia -- C/Mayor/3
2021-12-11 11:23:31,324 - root - INFO - Enviando secuencia -- C/Mayor/3
2021-12-11 11:23:58,242 - root - INFO - Enviando secuencia -- C/Mayor/3
2021-12-11 11:24:29,729 - root - INFO - Enviando secuencia -- C/Mayor/3
2021-12-11 11:25:23,433 - root - INFO - Enviando secuencia -- C/Mayor/3
2021-12-11 11:25:35,080 - root - INFO - Enviando secuencia -- C/Mayor/3
2021-12-11 11:26:10,287 - root - INFO - Enviando secuencia -- C/Mayor/4
2021-12-11 11:46:15,397 - root - INFO - Sending Dict/Lect -- dict/m/Audioperceptiva/4
2021-12-11 12:15:12,983 - root - INFO - Sending Dict/Lect -- dict/r/Audioperceptiva/D
2021-12-11 12:30:19,177 - root - INFO - Sending Dict/Lect -- lect/r/Audioperceptiva/C
2021-12-11 12:31:06,712 - root - INFO - Sending Dict/Lect -- lect/r/Audioperceptiva/D
2021-12-11 12:36:08,631 - root - INFO - Sending Dict/Lect -- lect/m/Audioperceptiva/4
2021-12-11 12:42:06,405 - telegram.vendor.ptb_urllib3.urllib3.connectionpool - WARNING - Retrying (Retry(total=2, connect=None, read=None, redirect=None)) after connection broken by 'NewConnectionError('<telegram.vendor.ptb_urllib3.urllib3.connection.VerifiedHTTPSConnection object at 0x7fdd80e8c100>: Failed to establish a new connection: [Errno 101] Network is unreachable')': /bot1965896728:AAFgG4MTLoLy8QnqINF4qLm4_umRJM7DJHo/getUpdates
2021-12-11 14:07:18,680 - root - INFO - Sending Melo/Hind -- hind/X/141a
2021-12-11 14:12:25,589 - telegram.vendor.ptb_urllib3.urllib3.connectionpool - WARNING - Retrying (Retry(total=2, connect=None, read=None, redirect=None)) after connection broken by 'ConnectTimeoutError(<telegram.vendor.ptb_urllib3.urllib3.connectionpool.HTTPSConnectionPool object at 0x7fdd847ea3a0>, 'Connect timed out. (connect timeout=5.0)')': /bot1965896728:AAFgG4MTLoLy8QnqINF4qLm4_umRJM7DJHo/getUpdates
2021-12-11 14:12:30,608 - telegram.vendor.ptb_urllib3.urllib3.connectionpool - WARNING - Retrying (Retry(total=1, connect=None, read=None, redirect=None)) after connection broken by 'NewConnectionError('<telegram.vendor.ptb_urllib3.urllib3.connection.VerifiedHTTPSConnection object at 0x7fdd80e744f0>: Failed to establish a new connection: [Errno 101] Network is unreachable')': /bot1965896728:AAFgG4MTLoLy8QnqINF4qLm4_umRJM7DJHo/getUpdates
2021-12-11 14:37:16,332 - telegram.vendor.ptb_urllib3.urllib3.connectionpool - WARNING - Retrying (Retry(total=2, connect=None, read=None, redirect=None)) after connection broken by 'NewConnectionError('<telegram.vendor.ptb_urllib3.urllib3.connection.VerifiedHTTPSConnection object at 0x7fdd80e8c100>: Failed to establish a new connection: [Errno 101] Network is unreachable')': /bot1965896728:AAFgG4MTLoLy8QnqINF4qLm4_umRJM7DJHo/getUpdates
2021-12-11 22:13:56,625 - root - INFO - Enviando secuencia -- E/Menor natural/4
2021-12-11 23:11:45,647 - root - INFO - Sending Dict/Lect -- lect/m/Audioperceptiva/1
2021-12-11 23:15:56,705 - root - INFO - Sending Dict/Lect -- lect/r/Audioperceptiva/5
2021-12-11 23:15:57,112 - root - ERROR - [Errno 2] No such file or directory: 'lect/r/Audioperceptiva/5.png'
2021-12-12 09:10:11,759 - telegram.ext.updater - ERROR - Error while getting Updates: urllib3 HTTPError ('Connection aborted.', ConnectionResetError(104, 'Connection reset by peer'))
2021-12-12 09:10:11,760 - root - ERROR - urllib3 HTTPError ('Connection aborted.', ConnectionResetError(104, 'Connection reset by peer'))
2021-12-12 09:10:12,778 - telegram.ext.dispatcher - ERROR - An uncaught error was raised while handling the error.
Traceback (most recent call last):
  File "/usr/local/lib/python3.8/dist-packages/telegram/ext/dispatcher.py", line 536, in process_update
    self.dispatch_error(None, update)
  File "/usr/local/lib/python3.8/dist-packages/telegram/ext/dispatcher.py", line 810, in dispatch_error
    callback(update, context)
  File "BotTyP4.py", line 471, in error
    context.bot.sendMessage(chat_id=update.effective_chat.id,
AttributeError: 'NoneType' object has no attribute 'effective_chat'
2021-12-12 09:10:23,368 - telegram.ext.updater - ERROR - Error while getting Updates: urllib3 HTTPError ('Connection aborted.', ConnectionResetError(104, 'Connection reset by peer'))
2021-12-12 09:10:23,370 - root - ERROR - urllib3 HTTPError ('Connection aborted.', ConnectionResetError(104, 'Connection reset by peer'))
2021-12-12 09:10:24,321 - telegram.ext.dispatcher - ERROR - An uncaught error was raised while handling the error.
Traceback (most recent call last):
  File "/usr/local/lib/python3.8/dist-packages/telegram/ext/dispatcher.py", line 536, in process_update
    self.dispatch_error(None, update)
  File "/usr/local/lib/python3.8/dist-packages/telegram/ext/dispatcher.py", line 810, in dispatch_error
    callback(update, context)
  File "BotTyP4.py", line 471, in error
    context.bot.sendMessage(chat_id=update.effective_chat.id,
AttributeError: 'NoneType' object has no attribute 'effective_chat'
2021-12-12 09:45:52,122 - root - INFO - Enviando secuencia -- C/Mayor/3
2021-12-12 09:47:10,414 - root - INFO - Enviando secuencia -- C/Mayor/3
2021-12-12 09:47:21,164 - root - INFO - Enviando secuencia -- C/Mayor/3
2021-12-12 09:47:39,137 - root - INFO - Enviando secuencia -- C/Mayor/3
2021-12-12 09:48:07,083 - root - INFO - Enviando secuencia -- C/Mayor/3
2021-12-12 09:48:20,072 - root - INFO - Enviando secuencia -- C/Mayor/3
2021-12-12 09:49:10,156 - root - INFO - Sending Dict/Lect -- dict/m/Audioperceptiva/5
2021-12-12 10:12:58,617 - root - ERROR - Message is not modified: specified new message content and reply markup are exactly the same as a current content and reply markup of the message
2021-12-12 10:17:21,955 - root - INFO - Sending Dict/Lect -- dict/r/Audioperceptiva/E
2021-12-12 10:37:34,669 - root - INFO - Sending Dict/Lect -- lect/m/Audioperceptiva/5
2021-12-12 10:57:47,078 - root - INFO - Sending Dict/Lect -- dict/r/Audioperceptiva/E
2021-12-12 10:58:33,416 - root - INFO - Sending Dict/Lect -- lect/r/Audioperceptiva/E
2021-12-12 11:29:07,802 - root - INFO - Sending Dict/Lect -- lect/m/Audioperceptiva/1
2021-12-12 11:32:48,285 - root - INFO - Sending Dict/Lect -- lect/m/Audioperceptiva/2
2021-12-12 13:13:24,556 - root - INFO - Sending Dict/Lect -- dict/m/Audioperceptiva/5
2021-12-12 13:40:55,490 - root - INFO - Sending Dict/Lect -- dict/r/Audioperceptiva/C
2021-12-12 13:46:17,312 - root - INFO - Sending Dict/Lect -- lect/r/Audioperceptiva/B
2021-12-12 13:46:50,979 - root - INFO - Sending Dict/Lect -- lect/r/Audioperceptiva/A
2021-12-12 13:47:00,808 - root - INFO - Sending Dict/Lect -- lect/r/Audioperceptiva/C
2021-12-12 13:47:12,465 - root - INFO - Sending Dict/Lect -- lect/r/Audioperceptiva/D
2021-12-12 13:47:22,642 - root - INFO - Sending Dict/Lect -- lect/r/Audioperceptiva/E
2021-12-12 13:53:39,836 - root - INFO - Sending Dict/Lect -- lect/m/Audioperceptiva/1
2021-12-12 13:53:51,822 - root - INFO - Sending Dict/Lect -- lect/m/Audioperceptiva/2
2021-12-12 13:54:06,033 - root - INFO - Sending Dict/Lect -- lect/m/Audioperceptiva/3
2021-12-12 13:54:20,210 - root - INFO - Sending Dict/Lect -- lect/m/Audioperceptiva/4
2021-12-12 13:54:29,553 - root - INFO - Sending Dict/Lect -- lect/m/Audioperceptiva/5
2021-12-12 19:27:42,670 - root - INFO - Enviando secuencia -- C/Mayor/4
2021-12-12 19:29:37,265 - root - INFO - Enviando secuencia -- C/Mayor/4
2021-12-12 19:30:56,501 - root - INFO - Enviando secuencia -- C/Mayor/4
2021-12-12 19:31:42,016 - root - INFO - Enviando secuencia -- C/Mayor/4
2021-12-12 19:57:04,946 - telegram.vendor.ptb_urllib3.urllib3.connectionpool - WARNING - Retrying (Retry(total=2, connect=None, read=None, redirect=None)) after connection broken by 'ConnectTimeoutError(<telegram.vendor.ptb_urllib3.urllib3.connectionpool.HTTPSConnectionPool object at 0x7fdd847ea3a0>, 'Connect timed out. (connect timeout=5.0)')': /bot1965896728:AAFgG4MTLoLy8QnqINF4qLm4_umRJM7DJHo/getUpdates
2021-12-12 22:23:11,789 - root - INFO - Enviando secuencia -- F/Mayor/4
2021-12-12 22:23:39,330 - root - INFO - Enviando secuencia -- F/Mayor/4
2021-12-12 22:23:53,989 - root - INFO - Enviando secuencia -- F/Mayor/4
2021-12-12 22:24:17,106 - root - INFO - Sending Melo/Hind -- melo/IX/282
2021-12-12 23:22:17,445 - root - INFO - Enviando secuencia -- C/Mayor/4
2021-12-12 23:23:02,270 - root - INFO - Enviando secuencia -- C/Mayor/4
2021-12-12 23:23:38,121 - root - ERROR - Message is not modified: specified new message content and reply markup are exactly the same as a current content and reply markup of the message
2021-12-12 23:23:45,314 - root - INFO - Enviando secuencia -- C/Mayor/6
2021-12-12 23:25:47,402 - root - INFO - Enviando secuencia -- C/Mayor/6
2021-12-13 05:55:55,585 - root - INFO - Enviando secuencia -- C/Mayor/3
2021-12-13 05:56:27,624 - root - INFO - Enviando secuencia -- C/Mayor/3
2021-12-13 05:56:45,161 - root - INFO - Enviando secuencia -- C/Mayor/3
2021-12-13 05:56:57,066 - root - INFO - Enviando secuencia -- C/Mayor/3
2021-12-13 05:57:33,881 - root - INFO - Enviando secuencia -- C/Mayor/3
2021-12-13 05:57:49,464 - root - INFO - Enviando secuencia -- C/Mayor/3
2021-12-13 05:58:17,632 - root - INFO - Enviando secuencia -- C/Mayor/3
2021-12-13 06:39:13,106 - root - INFO - Enviando secuencia -- C/Mayor/3
2021-12-13 07:12:24,102 - root - ERROR - Message is not modified: specified new message content and reply markup are exactly the same as a current content and reply markup of the message
2021-12-13 07:12:36,316 - root - ERROR - Message is not modified: specified new message content and reply markup are exactly the same as a current content and reply markup of the message
2021-12-13 07:39:51,853 - telegram.ext.updater - ERROR - Error while getting Updates: urllib3 HTTPError ('Connection aborted.', ConnectionResetError(104, 'Connection reset by peer'))
2021-12-13 07:39:51,881 - root - ERROR - urllib3 HTTPError ('Connection aborted.', ConnectionResetError(104, 'Connection reset by peer'))
2021-12-13 07:39:52,865 - telegram.ext.dispatcher - ERROR - An uncaught error was raised while handling the error.
Traceback (most recent call last):
  File "/usr/local/lib/python3.8/dist-packages/telegram/ext/dispatcher.py", line 536, in process_update
    self.dispatch_error(None, update)
  File "/usr/local/lib/python3.8/dist-packages/telegram/ext/dispatcher.py", line 810, in dispatch_error
    callback(update, context)
  File "BotTyP4.py", line 471, in error
    context.bot.sendMessage(chat_id=update.effective_chat.id,
AttributeError: 'NoneType' object has no attribute 'effective_chat'
2021-12-13 07:40:03,391 - telegram.ext.updater - ERROR - Error while getting Updates: urllib3 HTTPError ('Connection aborted.', ConnectionResetError(104, 'Connection reset by peer'))
2021-12-13 07:40:03,394 - root - ERROR - urllib3 HTTPError ('Connection aborted.', ConnectionResetError(104, 'Connection reset by peer'))
2021-12-13 07:40:04,387 - telegram.ext.dispatcher - ERROR - An uncaught error was raised while handling the error.
Traceback (most recent call last):
  File "/usr/local/lib/python3.8/dist-packages/telegram/ext/dispatcher.py", line 536, in process_update
    self.dispatch_error(None, update)
  File "/usr/local/lib/python3.8/dist-packages/telegram/ext/dispatcher.py", line 810, in dispatch_error
    callback(update, context)
  File "BotTyP4.py", line 471, in error
    context.bot.sendMessage(chat_id=update.effective_chat.id,
AttributeError: 'NoneType' object has no attribute 'effective_chat'
2021-12-13 10:34:43,152 - root - INFO - Sending Dict/Lect -- dict/m/Audioperceptiva/3
2021-12-13 16:27:32,801 - telegram.vendor.ptb_urllib3.urllib3.connectionpool - WARNING - Retrying (Retry(total=2, connect=None, read=None, redirect=None)) after connection broken by 'ConnectTimeoutError(<telegram.vendor.ptb_urllib3.urllib3.connectionpool.HTTPSConnectionPool object at 0x7fdd847ea3a0>, 'Connect timed out. (connect timeout=5.0)')': /bot1965896728:AAFgG4MTLoLy8QnqINF4qLm4_umRJM7DJHo/getUpdates
2021-12-13 16:27:37,820 - telegram.vendor.ptb_urllib3.urllib3.connectionpool - WARNING - Retrying (Retry(total=1, connect=None, read=None, redirect=None)) after connection broken by 'NewConnectionError('<telegram.vendor.ptb_urllib3.urllib3.connection.VerifiedHTTPSConnection object at 0x7fdd80e33c70>: Failed to establish a new connection: [Errno 101] Network is unreachable')': /bot1965896728:AAFgG4MTLoLy8QnqINF4qLm4_umRJM7DJHo/getUpdates
2021-12-13 17:50:08,434 - telegram.vendor.ptb_urllib3.urllib3.connectionpool - WARNING - Retrying (Retry(total=2, connect=None, read=None, redirect=None)) after connection broken by 'ConnectTimeoutError(<telegram.vendor.ptb_urllib3.urllib3.connectionpool.HTTPSConnectionPool object at 0x7fdd847ea3a0>, 'Connect timed out. (connect timeout=5.0)')': /bot1965896728:AAFgG4MTLoLy8QnqINF4qLm4_umRJM7DJHo/getUpdates
2021-12-13 18:56:57,335 - root - INFO - Enviando solfeo -- solf/Suffern/2
2021-12-13 18:57:40,346 - root - INFO - Sending .pdf file -- Cuadernillo Audio 
2021-12-13 20:13:00,985 - telegram.vendor.ptb_urllib3.urllib3.connectionpool - WARNING - Retrying (Retry(total=2, connect=None, read=None, redirect=None)) after connection broken by 'NewConnectionError('<telegram.vendor.ptb_urllib3.urllib3.connection.VerifiedHTTPSConnection object at 0x7fdd80e339a0>: Failed to establish a new connection: [Errno -3] Temporary failure in name resolution')': /bot1965896728:AAFgG4MTLoLy8QnqINF4qLm4_umRJM7DJHo/getUpdates
2021-12-13 20:13:06,309 - telegram.vendor.ptb_urllib3.urllib3.connectionpool - WARNING - Retrying (Retry(total=1, connect=None, read=None, redirect=None)) after connection broken by 'ConnectTimeoutError(<telegram.vendor.ptb_urllib3.urllib3.connectionpool.HTTPSConnectionPool object at 0x7fdd847ea3a0>, 'Connect timed out. (connect timeout=5.0)')': /bot1965896728:AAFgG4MTLoLy8QnqINF4qLm4_umRJM7DJHo/getUpdates
2021-12-13 20:28:40,720 - root - ERROR - Message is not modified: specified new message content and reply markup are exactly the same as a current content and reply markup of the message
2021-12-13 20:30:16,134 - root - ERROR - Message is not modified: specified new message content and reply markup are exactly the same as a current content and reply markup of the message
2021-12-13 21:37:43,754 - telegram.vendor.ptb_urllib3.urllib3.connectionpool - WARNING - Retrying (Retry(total=2, connect=None, read=None, redirect=None)) after connection broken by 'NewConnectionError('<telegram.vendor.ptb_urllib3.urllib3.connection.VerifiedHTTPSConnection object at 0x7fdd80e483a0>: Failed to establish a new connection: [Errno -3] Temporary failure in name resolution')': /bot1965896728:AAFgG4MTLoLy8QnqINF4qLm4_umRJM7DJHo/getUpdates
2021-12-13 21:44:30,740 - root - INFO - Reporting
2021-12-13 21:44:31,871 - root - INFO - Reporting
2021-12-13 21:44:32,649 - root - ERROR - Message is not modified: specified new message content and reply markup are exactly the same as a current content and reply markup of the message
2021-12-13 21:44:38,167 - root - INFO - Reporting
2021-12-13 21:44:46,692 - root - INFO - Sending .pdf file -- Suffern
2021-12-13 21:45:35,764 - root - INFO - Sending Melo/Hind -- melo/XI/366
2021-12-13 21:45:39,329 - root - INFO - Sending Melo/Hind -- melo/XI/366
2021-12-13 21:45:39,715 - root - ERROR - Message is not modified: specified new message content and reply markup are exactly the same as a current content and reply markup of the message
2021-12-13 21:52:47,646 - telegram.ext.updater - INFO - Received signal 2 (SIGINT), stopping...
2021-12-13 21:52:48,826 - apscheduler.scheduler - INFO - Scheduler has been shut down
2021-12-13 21:53:45,376 - apscheduler.scheduler - INFO - Scheduler started
2021-12-13 21:54:03,386 - root - INFO - Reporting
2021-12-13 21:54:04,230 - root - INFO - Reporting
2021-12-13 21:54:05,305 - root - ERROR - Message is not modified: specified new message content and reply markup are exactly the same as a current content and reply markup of the message
2021-12-13 21:55:49,324 - telegram.ext.updater - INFO - Received signal 2 (SIGINT), stopping...
2021-12-13 21:55:49,324 - apscheduler.scheduler - INFO - Scheduler has been shut down
2021-12-13 21:56:08,072 - apscheduler.scheduler - INFO - Scheduler started
2021-12-13 21:56:30,209 - root - INFO - Reporting
2021-12-13 21:56:31,008 - root - INFO - Reporting
2021-12-13 21:56:31,800 - root - ERROR - Message is not modified: specified new message content and reply markup are exactly the same as a current content and reply markup of the message
2021-12-13 21:57:17,570 - telegram.ext.updater - INFO - Received signal 2 (SIGINT), stopping...
2021-12-13 21:57:17,571 - apscheduler.scheduler - INFO - Scheduler has been shut down
2021-12-13 21:57:27,428 - apscheduler.scheduler - INFO - Scheduler started
2021-12-13 22:05:35,786 - telegram.ext.updater - INFO - Received signal 2 (SIGINT), stopping...
2021-12-13 22:05:35,787 - apscheduler.scheduler - INFO - Scheduler has been shut down
2021-12-13 22:05:49,399 - apscheduler.scheduler - INFO - Scheduler started
2021-12-13 22:05:59,522 - root - INFO - Reporting
2021-12-13 22:06:00,297 - root - INFO - Reporting
2021-12-13 22:06:01,045 - root - ERROR - Message is not modified: specified new message content and reply markup are exactly the same as a current content and reply markup of the message
2021-12-13 22:08:01,928 - root - INFO - Reporting
2021-12-13 22:08:02,693 - root - INFO - Reporting
2021-12-13 22:08:03,468 - root - ERROR - Message is not modified: specified new message content and reply markup are exactly the same as a current content and reply markup of the message
2021-12-13 22:08:18,384 - root - ERROR - Message is not modified: specified new message content and reply markup are exactly the same as a current content and reply markup of the message
2021-12-13 22:22:09,481 - telegram.ext.updater - INFO - Received signal 2 (SIGINT), stopping...
2021-12-13 22:22:09,797 - apscheduler.scheduler - INFO - Scheduler has been shut down
